<?xml version="1.0" ?>
<sdf version="1.7">
  <world name="collision_navigation_world">
    <!-- Include basic environment -->
    <include>
      <uri>model://ground_plane</uri>
    </include>

    <include>
      <uri>model://sun</uri>
    </include>

    <!-- Create a simple maze environment -->
    <!-- Walls -->
    <model name="wall_1">
      <pose>0 3 0.5 0 0 0</pose>
      <link name="wall_link">
        <inertial>
          <mass>100.0</mass>
          <inertia>
            <ixx>10</ixx>
            <ixy>0</ixy>
            <ixz>0</ixz>
            <iyy>10</iyy>
            <iyz>0</iyz>
            <izz>10</izz>
          </inertia>
        </inertial>
        <visual name="wall_visual">
          <geometry>
            <box>
              <size>6 0.2 1</size>
            </box>
          </geometry>
          <material>
            <ambient>0.5 0.5 0.5 1</ambient>
            <diffuse>0.5 0.5 0.5 1</diffuse>
          </material>
        </visual>
        <collision name="wall_collision">
          <geometry>
            <box>
              <size>6 0.2 1</size>
            </box>
          </geometry>
        </collision>
      </link>
    </model>

    <model name="wall_2">
      <pose>3 0 0.5 0 0 1.57</pose>
      <link name="wall_link">
        <inertial>
          <mass>100.0</mass>
          <inertia>
            <ixx>10</ixx>
            <ixy>0</ixy>
            <ixz>0</ixz>
            <iyy>10</iyy>
            <iyz>0</iyz>
            <izz>10</izz>
          </inertia>
        </inertial>
        <visual name="wall_visual">
          <geometry>
            <box>
              <size>6 0.2 1</size>
            </box>
          </geometry>
          <material>
            <ambient>0.5 0.5 0.5 1</ambient>
            <diffuse>0.5 0.5 0.5 1</diffuse>
          </material>
        </visual>
        <collision name="wall_collision">
          <geometry>
            <box>
              <size>6 0.2 1</size>
            </box>
          </geometry>
        </collision>
      </link>
    </model>

    <model name="wall_3">
      <pose>0 -3 0.5 0 0 0</pose>
      <link name="wall_link">
        <inertial>
          <mass>100.0</mass>
          <inertia>
            <ixx>10</ixx>
            <ixy>0</ixy>
            <ixz>0</ixz>
            <iyy>10</iyy>
            <iyz>0</iyz>
            <izz>10</izz>
          </inertia>
        </inertial>
        <visual name="wall_visual">
          <geometry>
            <box>
              <size>6 0.2 1</size>
            </box>
          </geometry>
          <material>
            <ambient>0.5 0.5 0.5 1</ambient>
            <diffuse>0.5 0.5 0.5 1</diffuse>
          </material>
        </visual>
        <collision name="wall_collision">
          <geometry>
            <box>
              <size>6 0.2 1</size>
            </box>
          </geometry>
        </collision>
      </link>
    </model>

    <model name="wall_4">
      <pose>-3 0 0.5 0 0 1.57</pose>
      <link name="wall_link">
        <inertial>
          <mass>100.0</mass>
          <inertia>
            <ixx>10</ixx>
            <ixy>0</ixy>
            <ixz>0</ixz>
            <iyy>10</iyy>
            <iyz>0</iyz>
            <izz>10</izz>
          </inertia>
        </inertial>
        <visual name="wall_visual">
          <geometry>
            <box>
              <size>6 0.2 1</size>
            </box>
          </geometry>
          <material>
            <ambient>0.5 0.5 0.5 1</ambient>
            <diffuse>0.5 0.5 0.5 1</diffuse>
          </material>
        </visual>
        <collision name="wall_collision">
          <geometry>
            <box>
              <size>6 0.2 1</size>
            </box>
          </geometry>
        </collision>
      </link>
    </model>

    <!-- Interior obstacles -->
    <model name="obstacle_1">
      <pose>1 1 0.3 0 0 0</pose>
      <link name="obstacle_link">
        <inertial>
          <mass>10.0</mass>
          <inertia>
            <ixx>0.5</ixx>
            <ixy>0</ixy>
            <ixz>0</ixz>
            <iyy>0.5</iyy>
            <iyz>0</iyz>
            <izz>0.5</izz>
          </inertia>
        </inertial>
        <visual name="obstacle_visual">
          <geometry>
            <cylinder>
              <radius>0.3</radius>
              <length>0.6</length>
            </cylinder>
          </geometry>
          <material>
            <ambient>0.8 0.2 0.2 1</ambient>
            <diffuse>0.8 0.2 0.2 1</diffuse>
          </material>
        </visual>
        <collision name="obstacle_collision">
          <geometry>
            <cylinder>
              <radius>0.3</radius>
              <length>0.6</length>
            </cylinder>
          </geometry>
        </collision>
      </link>
    </model>

    <model name="obstacle_2">
      <pose>-1.5 -1.5 0.5 0 0 0</pose>
      <link name="obstacle_link">
        <inertial>
          <mass>15.0</mass>
          <inertia>
            <ixx>0.8</ixx>
            <ixy>0</ixy>
            <ixz>0</ixz>
            <iyy>0.8</iyy>
            <iyz>0</iyz>
            <izz>0.8</izz>
          </inertia>
        </inertial>
        <visual name="obstacle_visual">
          <geometry>
            <box>
              <size>0.8 0.8 1</size>
            </box>
          </geometry>
          <material>
            <ambient>0.2 0.2 0.8 1</ambient>
            <diffuse>0.2 0.2 0.8 1</diffuse>
          </material>
        </visual>
        <collision name="obstacle_collision">
          <geometry>
            <box>
              <size>0.8 0.8 1</size>
            </box>
          </geometry>
        </collision>
      </link>
    </model>

    <!-- Mobile robot -->
    <model name="mobile_robot">
      <pose>-2 -2 0.2 0 0 0</pose>
      <link name="chassis">
        <inertial>
          <mass>10.0</mass>
          <inertia>
            <ixx>0.4</ixx>
            <ixy>0</ixy>
            <ixz>0</ixz>
            <iyy>0.8</iyy>
            <iyz>0</iyz>
            <izz>0.8</izz>
          </inertia>
        </inertial>
        <visual name="chassis_visual">
          <geometry>
            <box>
              <size>0.5 0.3 0.2</size>
            </box>
          </geometry>
          <material>
            <ambient>0.2 0.8 0.2 1</ambient>
            <diffuse>0.2 0.8 0.2 1</diffuse>
          </material>
        </visual>
        <collision name="chassis_collision">
          <geometry>
            <box>
              <size>0.5 0.3 0.2</size>
            </box>
          </geometry>
        </collision>
      </link>

      <!-- Differential drive wheels -->
      <link name="left_wheel">
        <inertial>
          <mass>0.5</mass>
          <inertia>
            <ixx>0.001</ixx>
            <ixy>0</ixy>
            <ixz>0</ixz>
            <iyy>0.001</iyy>
            <iyz>0</iyz>
            <izz>0.002</izz>
          </inertia>
        </inertial>
        <visual name="wheel_visual">
          <geometry>
            <cylinder>
              <radius>0.1</radius>
              <length>0.05</length>
            </cylinder>
          </geometry>
          <material>
            <ambient>0.3 0.3 0.3 1</ambient>
            <diffuse>0.3 0.3 0.3 1</diffuse>
          </material>
        </visual>
        <collision name="wheel_collision">
          <geometry>
            <cylinder>
              <radius>0.1</radius>
              <length>0.05</length>
            </cylinder>
          </geometry>
        </collision>
      </link>

      <joint name="left_wheel_hinge" type="continuous">
        <parent>chassis</parent>
        <child>left_wheel</child>
        <pose>0.15 0.2 -0.1 0 0 0</pose>
        <axis>
          <xyz>0 1 0</xyz>
        </axis>
      </joint>

      <link name="right_wheel">
        <inertial>
          <mass>0.5</mass>
          <inertia>
            <ixx>0.001</ixx>
            <ixy>0</ixy>
            <ixz>0</ixz>
            <iyy>0.001</iyy>
            <iyz>0</iyz>
            <izz>0.002</izz>
          </inertia>
        </inertial>
        <visual name="wheel_visual">
          <geometry>
            <cylinder>
              <radius>0.1</radius>
              <length>0.05</length>
            </cylinder>
          </geometry>
          <material>
            <ambient>0.3 0.3 0.3 1</ambient>
            <diffuse>0.3 0.3 0.3 1</diffuse>
          </material>
        </visual>
        <collision name="wheel_collision">
          <geometry>
            <cylinder>
              <radius>0.1</radius>
              <length>0.05</length>
            </cylinder>
          </geometry>
        </collision>
      </link>

      <joint name="right_wheel_hinge" type="continuous">
        <parent>chassis</parent>
        <child>right_wheel</child>
        <pose>0.15 -0.2 -0.1 0 0 0</pose>
        <axis>
          <xyz>0 1 0</xyz>
        </axis>
      </joint>

      <!-- LiDAR sensor -->
      <link name="laser_link">
        <inertial>
          <mass>0.1</mass>
          <inertia>
            <ixx>0.0001</ixx>
            <ixy>0</ixy>
            <ixz>0</ixz>
            <iyy>0.0001</iyy>
            <iyz>0</iyz>
            <izz>0.0001</izz>
          </inertia>
        </inertial>
        <visual name="laser_visual">
          <geometry>
            <cylinder>
              <radius>0.02</radius>
              <length>0.04</length>
            </cylinder>
          </geometry>
        </visual>
        <collision name="laser_collision">
          <geometry>
            <cylinder>
              <radius>0.02</radius>
              <length>0.04</length>
            </cylinder>
          </geometry>
        </collision>
      </link>

      <joint name="laser_mount" type="fixed">
        <parent>chassis</parent>
        <child>laser_link</child>
        <pose>0.2 0 0.1 0 0 0</pose>
      </joint>

      <!-- LiDAR sensor plugin -->
      <sensor name="laser" type="ray">
        <pose>0 0 0 0 0 0</pose>
        <visualize>true</visualize>
        <update_rate>10</update_rate>
        <ray>
          <scan>
            <horizontal>
              <samples>360</samples>
              <resolution>1</resolution>
              <min_angle>-3.14159</min_angle>
              <max_angle>3.14159</max_angle>
            </horizontal>
          </scan>
          <range>
            <min>0.1</min>
            <max>5.0</max>
            <resolution>0.01</resolution>
          </range>
        </ray>
        <plugin name="laser_controller" filename="libgazebo_ros_ray_sensor.so">
          <ros>
            <namespace>/mobile_robot</namespace>
            <remapping>~/out:=scan</remapping>
          </ros>
          <output_type>sensor_msgs/LaserScan</output_type>
        </plugin>
      </sensor>

      <!-- Add ROS control plugin -->
      <plugin name="diff_drive" filename="libgazebo_ros_diff_drive.so">
        <ros>
          <namespace>/mobile_robot</namespace>
        </ros>
        <update_rate>30</update_rate>
        <left_joint>left_wheel_hinge</left_joint>
        <right_joint>right_wheel_hinge</right_joint>
        <wheel_separation>0.4</wheel_separation>
        <wheel_diameter>0.2</wheel_diameter>
        <max_wheel_torque>20</max_wheel_torque>
        <max_wheel_acceleration>1.0</max_wheel_acceleration>
        <command_topic>cmd_vel</command_topic>
        <odometry_topic>odom</odometry_topic>
        <odometry_frame>odom</odometry_frame>
        <robot_base_frame>chassis</robot_base_frame>
        <publish_odom>true</publish_odom>
        <publish_wheel_tf>false</publish_wheel_tf>
        <publish_odom_tf>true</publish_odom_tf>
      </plugin>
    </model>

    <!-- Goal marker -->
    <model name="goal">
      <pose>2 2 0.1 0 0 0</pose>
      <static>true</static>
      <link name="goal_link">
        <visual name="goal_visual">
          <geometry>
            <sphere>
              <radius>0.1</radius>
            </sphere>
          </geometry>
          <material>
            <ambient>0.8 0.8 0.2 1</ambient>
            <diffuse>0.8 0.8 0.2 1</diffuse>
          </material>
        </visual>
      </link>
    </model>

    <!-- Physics configuration -->
    <physics type="ode">
      <max_step_size>0.001</max_step_size>
      <real_time_factor>1.0</real_time_factor>
      <real_time_update_rate>1000</real_time_update_rate>
      <ode>
        <solver>
          <type>quick</type>
          <iters>100</iters>
          <sor>1.3</sor>
        </solver>
        <constraints>
          <cfm>0.0</cfm>
          <erp>0.2</erp>
          <contact_max_correcting_vel>100.0</contact_max_correcting_vel>
          <contact_surface_layer>0.001</contact_surface_layer>
        </constraints>
      </ode>
    </physics>
  </world>
</sdf>